Workbook

Sheet Premissas & Parâmetros
A1: NETFITS LTDA. — MATRIZ DE PREMISSAS, PARÂMETROS & CURVA DE USUÁRIOS
A2: Base de Parâmetros Operacionais, Alíquotas Fiscais, FinOps e Curva de Crescimento (Out/2026 a Dez/2030)
A4: Categoria / Parâmetro | B4: Valor de Referência | C4: Fator de Cálculo | D4: Descrição Funcional & Impacto no Modelo | F4: Mês / Ano | G4: Usuários Ativos (Base Oficial)
A5: GRUPO 1: MARKETPLACE SHOP (B2C) | F5: Oct/26 | G5: 100
A6: Take Rate Líquido Médio (Comissão Netfits) | B6: 8,0% | C6: 0.08 | D6: Percentual retido pela Netfits sobre o GMV dos sellers | F6: Nov/26 | G6: 500
A7: Ticket Médio de Gasto por Compra | B7: R$ 200,00 | C7: 200.00 | D7: Valor médio de cada transação de produtos e suplementos | F7: Dec/26 | G7: 1000
A8: Frequência de Compras por Cliente Ativo | B8: 1 compra / mês | C8: 1.00 | D8: Média de pedidos mensais por cliente comprador | F8: Jan/27 | G8: 1333
A9: Taxa de Conversão de Compradores no Shop | B9: 5,0% | C9: 0.05 | D9: % da base total de atletas que realizam compras mensais | F9: Feb/27 | G9: 1750
A10: Pontos nfs Emitidos por Real Gasto | B10: 2 nfs / R$ | C10: 2.00 | D10: Recompensa padrão de pontos no marketplace | F10: Mar/27 | G10: 5000
A11: GRUPO 2: PROGRAMA DE ASSOCIADOS & PARCEIROS (B2B) | F11: Apr/27 | G11: 15000
A12: Comissão de Revenue Share aos Associados | B12: 10,0% | C12: 0.10 | D12: Repasse aos médicos, nutricionistas e treinadores sobre a receita gerada | F12: May/27 | G12: 50000
A13: Taxa de Retenção de Clientes por Associado | B13: 85,0% | C13: 0.85 | D13: Fidelização média de alunos e pacientes na plataforma | F13: Jun/27 | G13: 100000
A14: Carência para Apuração de Estornos | B14: 30 a 60 dias | C14: 45 | D14: Janela de apuração contábil antes da liquidação do repasse | F14: Jul/27 | G14: 200000
A15: GRUPO 3: PROGRAMA DE PONTOS NFS & PASSIVO CIRCULANTE | F15: Aug/27 | G15: 500000
A16: Custo de Provisão de Pontos (CPP Emissão) | B16: R$ 0,010 | C16: 0.010 | D16: Provisão de caixa depositada a cada ponto nfs emitido | F16: Sep/27 | G16: 750000
A17: Custo de Resgate de Pontos (CPP Resgate) | B17: R$ 0,010 | C17: 0.010 | D17: Custo unitário do ponto quando resgatado em produtos/serviços | F17: Oct/27 | G17: 875000
A18: Spread de Preço de Pontos (Ganho Líquido) | B18: R$ 0,010 | C18: 0.010 | D18: Diferença entre emissão para parceiros e custo de resgate | F18: Nov/27 | G18: 950000
A19: Prazo de Expiração por Inatividade (FEFO) | B19: 360 dias | C19: 360 | D19: Cancelamento de saldo após 1 ano sem atividade esportiva | F19: Dec/27 | G19: 1000000
A20: GRUPO 4: MÍDIA, FEED & RETAIL MEDIA | F20: Jan/28 | G20: 1100000
A21: CPV (Custo por View com 100% Dwell Time) | B21: R$ 2,00 | C21: 2.00 | D21: Receita por visualização integral de vídeo publicitário | F21: Feb/28 | G21: 1200000
A22: CPC (Custo por Clique no Feed) | B22: R$ 5,00 | C22: 5.00 | D22: Receita por clique qualificado em anúncio institucional | F22: Mar/28 | G22: 1300000
A23: Taxa de Conversão de Views no Feed | B23: 2,0% | C23: 0.02 | D23: % de atletas que assistem vídeos patrocinados | F23: Apr/28 | G23: 1400000
A24: Taxa de Conversão de Clicks no Feed | B24: 1,0% | C24: 0.01 | D24: % de atletas que clicam em links patrocinados | F24: May/28 | G24: 1500000
A25: GRUPO 5: TRIBUTAÇÃO & REGIME FISCAL | F25: Jun/28 | G25: 1600000
A26: Alíquota Inicial (Simples Nacional) | B26: 6,0% | C26: 0.06 | D26: Tributação sobre serviços para faturamento até R$ 4,8M/ano | F26: Jul/28 | G26: 1675000
A27: Alíquota Lucro Presumido (São Paulo) | B27: 16,33% | C27: 0.1633 | D27: PIS/COFINS (3,65%) + IRPJ/CSLL (~7,68%) + ISS (5%) | F27: Aug/28 | G27: 1750000
A28: Alíquota Lucro Presumido (Barueri / Otimizado) | B28: 13,33% | C28: 0.1333 | D28: ISS reduzido de 2% a 3% + Tributos Federais | F28: Sep/28 | G28: 1825000
A29: GRUPO 6: FINOPS & SQUADS MULTIAGENTES DE IA | F29: Oct/28 | G29: 1890000
A30: Squad de IA de Operação (8 Agentes) | B30: R$ 2.840,00 / mês | C30: 2840.00 | D30: Substitui 14 profissionais com 96,8% de economia | F30: Nov/28 | G30: 1950000
A31: Squad de QA Autônomo (4 Agentes) | B31: R$ 48,60 / mês | C31: 48.60 | D31: Simulação de 24 personas e testes 24/7 com 99,8% de economia | F31: Dec/28 | G31: 2000000
A32: Economia Total FinOps com IA vs CLT | B32: R$ 116.311,40 / mês | C32: 116311.40 | D32: Economia transferida diretamente para a margem EBITDA | F32: Jan/29 | G32: 2050000
F33: Feb/29 | G33: 2100000
F34: Mar/29 | G34: 2150000
F35: Apr/29 | G35: 2200000
F36: May/29 | G36: 2250000
F37: Jun/29 | G37: 2300000
F38: Jul/29 | G38: 2350000
F39: Aug/29 | G39: 2400000
F40: Sep/29 | G40: 2450000
F41: Oct/29 | G41: 2500000
...

Sheet Orçado
A1: NETFITS LTDA. — DEMONSTRAÇÃO DO RESULTADO DO EXERCÍCIO (ORÇADO / BUSINESS CASE 2026-2030)
A2: Valores Planejados no Modelo de Negócios Oficial (Out/2026 a Dez/2030 - 51 Meses)
A4: Conta / Estrutura DRE | B4: Oct/26 | C4: Nov/26 | D4: Dec/26 | E4: Jan/27 | F4: Feb/27 | G4: Mar/27 | H4: Apr/27 | I4: May/27 | J4: Jun/27 | K4: Jul/27 | L4: Aug/27 | M4: Sep/27 | N4: Oct/27 | O4: Nov/27 | P4: Dec/27 | Q4: Jan/28 | R4: Feb/28 | S4: Mar/28 | T4: Apr/28 | U4: May/28 | V4: Jun/28 | W4: Jul/28 | X4: Aug/28 | Y4: Sep/28 | Z4: Oct/28 | AA4: Nov/28 | AB4: Dec/28 | AC4: Jan/29 | AD4: Feb/29 | AE4: Mar/29 | AF4: Apr/29 | AG4: May/29 | AH4: Jun/29 | AI4: Jul/29 | AJ4: Aug/29 | AK4: Sep/29 | AL4: Oct/29 | AM4: Nov/29 | AN4: Dec/29 | AO4: Jan/30 | AP4: Feb/30 | AQ4: Mar/30 | AR4: Apr/30 | AS4: May/30 | AT4: Jun/30 | AU4: Jul/30 | AV4: Aug/30 | AW4: Sep/30 | AX4: Oct/30 | AY4: Nov/30 | AZ4: Dec/30
A5: USUÁRIOS ATIVOS DA PLATAFORMA | B5: ='Premissas & Parâmetros'!G5 -> 100 | C5: ='Premissas & Parâmetros'!G6 -> 500 | D5: ='Premissas & Parâmetros'!G7 -> 1000 | E5: 1333 | F5: 1750 | G5: 5000 | H5: 15000 | I5: 50000 | J5: 100000 | K5: 200000 | L5: 500000 | M5: 750000 | N5: 875000 | O5: 950000 | P5: 1000000 | Q5: 1100000 | R5: 1200000 | S5: 1300000 | T5: 1400000 | U5: 1500000 | V5: 1600000 | W5: 1675000 | X5: 1750000 | Y5: 1825000 | Z5: 1890000 | AA5: 1950000 | AB5: 2000000 | AC5: 2050000 | AD5: 2100000 | AE5: 2150000 | AF5: 2200000 | AG5: 2250000 | AH5: 2300000 | AI5: 2350000 | AJ5: 2400000 | AK5: 2450000 | AL5: 2500000 | AM5: 2550000 | AN5: 2600000 | AO5: 2650000 | AP5: 2700000 | AQ5: 2750000 | AR5: 2800000 | AS5: 2850000 | AT5: 2900000 | AU5: 2950000 | AV5: 3000000 | AW5: 3000000 | AX5: 3000000 | AY5: 3000000 | AZ5: 3000000
A6: RECEITA BRUTA
A7: Receita Marketplace (Shop) | B7: 80 | C7: 400 | D7: 800 | E7: 1040 | F7: 1400 | G7: 4000 | H7: 12000 | I7: 40000 | J7: 80000 | K7: 160000 | L7: 400000 | M7: 600000 | N7: 700000 | O7: 760000 | P7: 800000 | Q7: 880000 | R7: 960000 | S7: 1040000 | T7: 1120000 | U7: 1200000 | V7: 1280000 | W7: 1340000 | X7: 1400000 | Y7: 1460000 | Z7: 1512000 | AA7: 1560000 | AB7: 1600000 | AC7: 1640000 | AD7: 1680000 | AE7: 1720000 | AF7: 1760000 | AG7: 1800000 | AH7: 1840000 | AI7: 1880000 | AJ7: 1920000 | AK7: 1960000 | AL7: 2000000 | AM7: 2040000 | AN7: 2080000 | AO7: 2120000 | AP7: 2160000 | AQ7: 2200000 | AR7: 2240000 | AS7: 2280000 | AT7: 2320000 | AU7: 2360000 | AV7: 2400000 | AW7: 2400000 | AX7: 2400000 | AY7: 2400000 | AZ7: 2400000
A8: Receita Clube de Assinatura (Fase 2) | B8: 0 | C8: 0 | D8: 0 | E8: 0 | F8: 0 | G8: 0 | H8: 0 | I8: 0 | J8: 0 | K8: 3980 | L8: 9950 | M8: 14925 | N8: 17412.5 | O8: 18905 | P8: 19900 | Q8: 21890 | R8: 23880 | S8: 25870 | T8: 27860 | U8: 29850 | V8: 31840 | W8: 33332.5 | X8: 34825 | Y8: 36317.5 | Z8: 37611 | AA8: 38805 | AB8: 39800 | AC8: 40795 | AD8: 41790 | AE8: 42785 | AF8: 43780 | AG8: 44775 | AH8: 45770 | AI8: 46765 | AJ8: 47760 | AK8: 48755 | AL8: 49750 | AM8: 50745 | AN8: 51740 | AO8: 52735 | AP8: 53730 | AQ8: 54725 | AR8: 55720 | AS8: 56715 | AT8: 57710 | AU8: 58705 | AV8: 59700 | AW8: 59700 | AX8: 59700 | AY8: 59700 | AZ8: 59700
A9: Receita Total Mídia (Feed Views & Clicks) | B9: 0 | C9: 0 | D9: 0 | E9: 119.97 | F9: 315 | G9: 2250 | H9: 13500 | I9: 45000 | J9: 90000 | K9: 180000 | L9: 450000 | M9: 675000 | N9: 787500 | O9: 855000 | P9: 900000 | Q9: 990000 | R9: 1080000 | S9: 1170000 | T9: 1260000 | U9: 1350000 | V9: 1440000 | W9: 1507500 | X9: 1575000 | Y9: 1642500 | Z9: 1701000 | AA9: 1755000 | AB9: 1800000 | AC9: 1845000 | AD9: 1890000 | AE9: 1935000 | AF9: 1980000 | AG9: 2025000 | AH9: 2070000 | AI9: 2115000 | AJ9: 2160000 | AK9: 2205000 | AL9: 2250000 | AM9: 2295000 | AN9: 2340000 | AO9: 2385000 | AP9: 2430000 | AQ9: 2475000 | AR9: 2520000 | AS9: 2565000 | AT9: 2610000 | AU9: 2655000 | AV9: 2700000 | AW9: 2700000 | AX9: 2700000 | AY9: 2700000 | AZ9: 2700000
A10: Receita Serviços de Saúde & Parceiros | B10: 0 | C10: 0 | D10: 0 | E10: 0 | F10: 0 | G10: 0 | H10: 0 | I10: 0 | J10: 0 | K10: 0 | L10: 0 | M10: 0 | N10: 49437.5 | O10: 53675 | P10: 56500 | Q10: 62150 | R10: 67800 | S10: 73450 | T10: 79100 | U10: 84750 | V10: 90400 | W10: 94637.5 | X10: 98875 | Y10: 103112.5 | Z10: 106785 | AA10: 110175 | AB10: 113000 | AC10: 115825 | AD10: 118650 | AE10: 121475 | AF10: 124300 | AG10: 127125 | AH10: 129950 | AI10: 132775 | AJ10: 135600 | AK10: 138425 | AL10: 141250 | AM10: 144075 | AN10: 146900 | AO10: 149725 | AP10: 152550 | AQ10: 155375 | AR10: 158200 | AS10: 161025 | AT10: 163850 | AU10: 166675 | AV10: 169500 | AW10: 169500 | AX10: 169500 | AY10: 169500 | AZ10: 169500
A11: Receita Venda de Pontos Corporativos (B2B) | B11: 0 | C11: 0 | D11: 0 | E11: 0 | F11: 0 | G11: 0 | H11: 0 | I11: 0 | J11: 0 | K11: 480000 | L11: 1200000 | M11: 1800000 | N11: 2100000 | O11: 2280000 | P11: 2400000 | Q11: 2640000 | R11: 2880000 | S11: 3120000 | T11: 3360000 | U11: 3600000 | V11: 3840000 | W11: 4020000 | X11: 4200000 | Y11: 4380000 | Z11: 4536000 | AA11: 4680000 | AB11: 4800000 | AC11: 4920000 | AD11: 5040000 | AE11: 5160000 | AF11: 5280000 | AG11: 5400000 | AH11: 5520000 | AI11: 5640000 | AJ11: 5760000 | AK11: 5880000 | AL11: 6000000 | AM11: 6120000 | AN11: 6240000 | AO11: 6360000 | AP11: 6480000 | AQ11: 6600000 | AR11: 6720000 | AS11: 6840000 | AT11: 6960000 | AU11: 7080000 | AV11: 7200000 | AW11: 7200000 | AX11: 7200000 | AY11: 7200000 | AZ11: 7200000
A12: TOTAL DA RECEITA BRUTA | B12: 80 | C12: 400 | D12: 800 | E12: 1159.97 | F12: 1715 | G12: 6250 | H12: 25500 | I12: 85000 | J12: 170000 | K12: 823980 | L12: 2059950 | M12: 3089925 | N12: 3654350 | O12: 3967580 | P12: 4176400 | Q12: 4594040 | R12: 5011680 | S12: 5429320 | T12: 5846960 | U12: 6264600 | V12: 6682240 | W12: 6995470 | X12: 7308700 | Y12: 7621930 | Z12: 7893396 | AA12: 8143980 | AB12: 8352800 | AC12: 8561620 | AD12: 8770440 | AE12: 8979260 | AF12: 9188080 | AG12: 9396900 | AH12: 9605720 | AI12: 9814540 | AJ12: 10023360 | AK12: 10232180 | AL12: 10441000 | AM12: 10649820 | AN12: 10858640 | AO12: 11067460 | AP12: 11276280 | AQ12: 11485100 | AR12: 11693920 | AS12: 11902740 | AT12: 12111560 | AU12: 12320380 | AV12: 12529200 | AW12: 12529200 | AX12: 12529200 | AY12: 12529200 | AZ12: 12529200
A13: DEDUÇÕES DA RECEITA BRUTA
A14: Impostos sobre a Receita Bruta (Simples / Lucro Presumido) | B14: 4.8 | C14: 24 | D14: 48 | E14: 69.5982 | F14: 102.9 | G14: 375 | H14: 1530 | I14: 5100 | J14: 10200 | K14: 0 | L14: 0 | M14: 0 | N14: 0 | O14: 0 | P14: 0 | Q14: 0 | R14: 0 | S14: 0 | T14: 0 | U14: 0 | V14: 0 | W14: 0 | X14: 0 | Y14: 0 | Z14: 0 | AA14: 0 | AB14: 0 | AC14: 0 | AD14: 0 | AE14: 0 | AF14: 0 | AG14: 0 | AH14: 0 | AI14: 0 | AJ14: 0 | AK14: 0 | AL14: 0 | AM14: 0 | AN14: 0 | AO14: 0 | AP14: 0 | AQ14: 0 | AR14: 0 | AS14: 0 | AT14: 0 | AU14: 0 | AV14: 0 | AW14: 0 | AX14: 0 | AY14: 0 | AZ14: 0
A15: RECEITA LÍQUIDA TOTAL | B15: 75.2 | C15: 376 | D15: 752 | E15: 1090.3718 | F15: 1612.1 | G15: 5875 | H15: 23970 | I15: 79900 | J15: 159800 | K15: 823980 | L15: 2059950 | M15: 3089925 | N15: 3654350 | O15: 3967580 | P15: 4176400 | Q15: 4594040 | R15: 5011680 | S15: 5429320 | T15: 5846960 | U15: 6264600 | V15: 6682240 | W15: 6995470 | X15: 7308700 | Y15: 7621930 | Z15: 7893396 | AA15: 8143980 | AB15: 8352800 | AC15: 8561620 | AD15: 8770440 | AE15: 8979260 | AF15: 9188080 | AG15: 9396900 | AH15: 9605720 | AI15: 9814540 | AJ15: 10023360 | AK15: 10232180 | AL15: 10441000 | AM15: 10649820 | AN15: 10858640 | AO15: 11067460 | AP15: 11276280 | AQ15: 11485100 | AR15: 11693920 | AS15: 11902740 | AT15: 12111560 | AU15: 12320380 | AV15: 12529200 | AW15: 12529200 | AX15: 12529200 | AY15: 12529200 | AZ15: 12529200
A16: CUSTOS DIRETOS & ENCARGOS DO PROGRAMA
A17: Despesa com Provisão de Pontos nfs (R$ 0,01/nfs) | B17: 22 | C17: 110 | D17: 220 | E17: 240.9365 | F17: 321.13 | G17: 958.75 | H17: 3082.5 | I17: 10275 | J17: 20550 | K17: 320900 | L17: 802250 | M17: 1203375 | N17: 1229407.8 | O17: 1334785.6 | P17: 1405037.5 | Q17: 1545541.2 | R17: 1686045 | S17: 1826548.8 | T17: 1967052.5 | U17: 2107556.2 | V17: 2248060 | W17: 2353437.8 | X17: 2458815.6 | Y17: 2564193.4 | Z17: 2655520.9 | AA17: 2739823.1 | AB17: 2810075 | AC17: 2880326.9 | AD17: 2950578.8 | AE17: 3020830.6 | AF17: 3091082.5 | AG17: 3161334.4 | AH17: 3231586.2 | AI17: 3301838.1 | AJ17: 3372090 | AK17: 3442341.9 | AL17: 3512593.8 | AM17: 3582845.6 | AN17: 3653097.5 | AO17: 3723349.4 | AP17: 3793601.2 | AQ17: 3863853.1 | AR17: 3934105 | AS17: 4004356.9 | AT17: 4074608.8 | AU17: 4144860.6 | AV17: 4215112.5 | AW17: 4215112.5 | AX17: 4215112.5 | AY17: 4215112.5 | AZ17: 4215112.5
A18: Comissões & Repasses aos Associados (10% Revenue Share) | B18: -8 | C18: -40 | D18: -80 | E18: -115.997 | F18: -171.5 | G18: -625 | H18: -2550 | I18: -8500 | J18: -17000 | K18: -82398 | L18: -205995 | M18: -308992.5 | N18: -365435 | O18: -396758 | P18: -417640 | Q18: -459404 | R18: -501168 | S18: -542932 | T18: -584696 | U18: -626460 | V18: -668224 | W18: -699547 | X18: -730870 | Y18: -762193 | Z18: -789339.6 | AA18: -814398 | AB18: -835280 | AC18: -856162 | AD18: -877044 | AE18: -897926 | AF18: -918808 | AG18: -939690 | AH18: -960572 | AI18: -981454 | AJ18: -1002336 | AK18: -1023218 | AL18: -1044100 | AM18: -1064982 | AN18: -1085864 | AO18: -1106746 | AP18: -1127628 | AQ18: -1148510 | AR18: -1169392 | AS18: -1190274 | AT18: -1211156 | AU18: -1232038 | AV18: -1252920 | AW18: -1252920 | AX18: -1252920 | AY18: -1252920 | AZ18: -1252920
A19: Spread de Preço de Pontos (Emissão vs Resgate) | B19: 0 | C19: 0 | D19: 0 | E19: 55.986 | F19: 73.5 | G19: 210 | H19: 630 | I19: 2100 | J19: 4200 | K19: 8400 | L19: 21000 | M19: 31500 | N19: 224875 | O19: 244150 | P19: 257000 | Q19: 282700 | R19: 308400 | S19: 334100 | T19: 359800 | U19: 385500 | V19: 411200 | W19: 430475 | X19: 449750 | Y19: 469025 | Z19: 485730 | AA19: 501150 | AB19: 514000 | AC19: 526850 | AD19: 539700 | AE19: 552550 | AF19: 565400 | AG19: 578250 | AH19: 591100 | AI19: 603950 | AJ19: 616800 | AK19: 629650 | AL19: 642500 | AM19: 655350 | AN19: 668200 | AO19: 681050 | AP19: 693900 | AQ19: 706750 | AR19: 719600 | AS19: 732450 | AT19: 745300 | AU19: 758150 | AV19: 771000 | AW19: 771000 | AX19: 771000 | AY19: 771000 | AZ19: 771000
A20: MARGEM DE CONTRIBUIÇÃO (RECEITA PÓS ENCARGOS) | B20: 45.2 | C20: 226 | D20: 452 | E20: 789.4243 | F20: 1192.97 | G20: 4501.25 | H20: 18967.5 | I20: 63225 | J20: 126450 | K20: 429082 | L20: 1072705 | M20: 1609057.5 | N20: 2284382.2 | O20: 2480186.4 | P20: 2610722.5 | Q20: 2871794.8 | R20: 3132867 | S20: 3393939.2 | T20: 3655011.5 | U20: 3916083.8 | V20: 4177156 | W20: 4372960.2 | X20: 4568764.4 | Y20: 4764568.6 | Z20: 4934265.5 | AA20: 5090908.9 | AB20: 5221445 | AC20: 5351981.1 | AD20: 5482517.2 | AE20: 5613053.4 | AF20: 5743589.5 | AG20: 5874125.6 | AH20: 6004661.8 | AI20: 6135197.9 | AJ20: 6265734 | AK20: 6396270.1 | AL20: 6526806.2 | AM20: 6657342.4 | AN20: 6787878.5 | AO20: 6918414.6 | AP20: 7048950.8 | AQ20: 7179486.9 | AR20: 7310023 | AS20: 7440559.1 | AT20: 7571095.2 | AU20: 7701631.4 | AV20: 7832167.5 | AW20: 7832167.5 | AX20: 7832167.5 | AY20: 7832167.5 | AZ20: 7832167.5
A21: DESPESAS OPERACIONAIS (OPEX)
A22: 1. Pessoal & Pró-Labore da Diretoria | B22: 0 | C22: 0 | D22: 0 | E22: -50000 | F22: -50000 | G22: -50000 | H22: -50000 | I22: -50000 | J22: -50000 | K22: -150000 | L22: -150000 | M22: -150000 | N22: -150000 | O22: -150000 | P22: -150000 | Q22: -165000 | R22: -165000 | S22: -165000 | T22: -165000 | U22: -165000 | V22: -165000 | W22: -165000 | X22: -165000 | Y22: -165000 | Z22: -165000 | AA22: -165000 | AB22: -165000 | AC22: -181500 | AD22: -181500 | AE22: -181500 | AF22: -181500 | AG22: -181500 | AH22: -181500 | AI22: -181500 | AJ22: -181500 | AK22: -181500 | AL22: -181500 | AM22: -181500 | AN22: -181500 | AO22: -199650 | AP22: -199650 | AQ22: -199650 | AR22: -199650 | AS22: -199650 | AT22: -199650 | AU22: -199650 | AV22: -199650 | AW22: -199650 | AX22: -199650 | AY22: -199650 | AZ22: -199650
A23: 2. Squad de Agentes de IA Autônomos (8 Operação + 4 QA) | B23: -71.72 | C23: -251 | D23: -605.19 | E23: -885.07 | F23: -1105.78 | G23: -1295.19 | H23: -1381.83 | I23: -1464.28 | J23: -1543.1 | K23: -1618.79 | L23: -1762.1 | M23: -1896.53 | N23: -2023.65 | O23: -2144.58 | P23: -2177.21 | Q23: -2209.44 | R23: -2241.26 | S23: -2272.75 | T23: -2303.9 | U23: -2334.68 | V23: -2365.17 | W23: -2395.31 | X23: -2425.2 | Y23: -2454.76 | Z23: -2484.02 | AA23: -2513.02 | AB23: -2541.74 | AC23: -2570.22 | AD23: -2598.45 | AE23: -2626.41 | AF23: -2654.14 | AG23: -2681.66 | AH23: -2708.92 | AI23: -2735.96 | AJ23: -2762.81 | AK23: -2789.43 | AL23: -2815.86 | AM23: -2842.08 | AN23: -2868.11 | AO23: -2893.96 | AP23: -2919.61 | AQ23: -2945.1 | AR23: -2970.38 | AS23: -2995.52 | AT23: -3020.46 | AU23: -3045.27 | AV23: -3069.88 | AW23: -3094.37 | AX23: -3118.66 | AY23: -3142.84 | AZ23: -114637.37
A24: 3. Infraestrutura Cloud, Servidores & Edge (Nitro/Cloudflare) | B24: -111.51 | C24: -595.6 | D24: -1925.93 | E24: -3194.47 | F24: -4295.56 | G24: -5300.34 | H24: -5776.77 | I24: -6239.16 | J24: -6689.3 | K24: -7128.58 | L24: -7978.92 | M24: -8797.19 | N24: -9588.43 | O24: -10356.41 | P24: -10566.03 | Q24: -10774.13 | R24: -10980.76 | S24: -11186 | T24: -11389.83 | U24: -11592.36 | V24: -11793.6 | W24: -11993.58 | X24: -12192.38 | Y24: -12389.97 | Z24: -12586.42 | AA24: -12781.77 | AB24: -12976.01 | AC24: -13169.19 | AD24: -13361.35 | AE24: -13552.49 | AF24: -13742.68 | AG24: -13931.89 | AH24: -14120.16 | AI24: -14307.54 | AJ24: -14494.01 | AK24: -14679.6 | AL24: -14864.34 | AM24: -15048.25 | AN24: -15231.34 | AO24: -15413.64 | AP24: -15595.13 | AQ24: -15775.87 | AR24: -15955.86 | AS24: -16135.1 | AT24: -16313.6 | AU24: -16491.4 | AV24: -16668.51 | AW24: -16844.93 | AX24: -17020.68 | AY24: -17195.77 | AZ24: -581094.34
A25: 4. Estrutura de Dados, Ledger & Analytics (Postgres/BigQuery) | B25: -84.91 | C25: -471.92 | D25: -1565.4 | E25: -2623.76 | F25: -3549.26 | G25: -4397.82 | H25: -4801.26 | I25: -5193.42 | J25: -5575.71 | K25: -5949.21 | L25: -6673.44 | M25: -7371.66 | N25: -8047.96 | O25: -8705.34 | P25: -8884.93 | Q25: -9063.28 | R25: -9240.44 | S25: -9416.44 | T25: -9591.32 | U25: -9765.12 | V25: -9937.88 | W25: -10109.6 | X25: -10280.35 | Y25: -10450.13 | Z25: -10618.97 | AA25: -10786.89 | AB25: -10953.94 | AC25: -11120.11 | AD25: -11285.43 | AE25: -11449.94 | AF25: -11613.64 | AG25: -11776.55 | AH25: -11938.71 | AI25: -12100.12 | AJ25: -12260.79 | AK25: -12420.75 | AL25: -12579.99 | AM25: -12738.56 | AN25: -12896.45 | AO25: -13053.69 | AP25: -13210.28 | AQ25: -13366.25 | AR25: -13521.59 | AS25: -13676.33 | AT25: -13830.47 | AU25: -13984.01 | AV25: -14136.99 | AW25: -14289.4 | AX25: -14441.27 | AY25: -14592.59 | AZ25: -490394.27
A26: 5. CRM, WhatsApp API Transacional & Mensageria Omnichannel | B26: -21.09 | C26: -130 | D26: -463.66 | E26: -801.86 | F26: -1104.78 | G26: -1386.84 | H26: -1522.14 | I26: -1654.34 | J26: -1783.78 | K26: -1910.79 | L26: -2158.4 | M26: -2398.69 | N26: -2632.76 | O26: -2861.44 | P26: -2924.09 | Q26: -2986.39 | R26: -3048.35 | S26: -3109.98 | T26: -3171.28 | U26: -3232.26 | V26: -3292.96 | W26: -3353.35 | X26: -3413.46 | Y26: -3473.3 | Z26: -3532.86 | AA26: -3592.15 | AB26: -3651.19 | AC26: -3709.96 | AD26: -3768.49 | AE26: -3826.8 | AF26: -3884.87 | AG26: -3942.7 | AH26: -4000.32 | AI26: -4057.71 | AJ26: -4114.89 | AK26: -4171.85 | AL26: -4228.62 | AM26: -4285.18 | AN26: -4341.55 | AO26: -4397.73 | AP26: -4453.7 | AQ26: -4509.51 | AR26: -4565.12 | AS26: -4620.56 | AT26: -4675.82 | AU26: -4730.91 | AV26: -4785.83 | AW26: -4840.59 | AX26: -4895.19 | AY26: -4949.61 | AZ26: -163369.7
A27: 6. Segurança, Observabilidade & Ferramentas FinOps | B27: -22.34 | C27: -125 | D27: -416.67 | E27: -699.88 | F27: -947.94 | G27: -1175.62 | H27: -1283.94 | I27: -1389.26 | J27: -1491.97 | K27: -1592.35 | L27: -1787.05 | M27: -1974.86 | N27: -2156.84 | O27: -2333.78 | P27: -2382.13 | Q27: -2430.15 | R27: -2477.86 | S27: -2525.25 | T27: -2572.35 | U27: -2619.16 | V27: -2665.69 | W27: -2711.95 | X27: -2757.95 | Y27: -2803.69 | Z27: -2849.19 | AA27: -2894.43 | AB27: -2939.45 | AC27: -2984.22 | AD27: -3028.78 | AE27: -3073.12 | AF27: -3117.25 | AG27: -3161.17 | AH27: -3204.87 | AI27: -3248.38 | AJ27: -3291.71 | AK27: -3334.83 | AL27: -3377.76 | AM27: -3420.53 | AN27: -3463.1 | AO27: -3505.51 | AP27: -3547.74 | AQ27: -3589.8 | AR27: -3631.69 | AS27: -3673.43 | AT27: -3715.01 | AU27: -3756.43 | AV27: -3797.7 | AW27: -3838.82 | AX27: -3879.79 | AY27: -3920.62 | AZ27: -131589.01
A28: 7. Despesas Administrativas & Gerais | B28: 0 | C28: 0 | D28: 0 | E28: 0 | F28: 0 | G28: 0 | H28: 0 | I28: 0 | J28: 0 | K28: 0 | L28: 0 | M28: 0 | N28: 0 | O28: 0 | P28: 0 | Q28: 0 | R28: 0 | S28: 0 | T28: 0 | U28: 0 | V28: 0 | W28: 0 | X28: 0 | Y28: 0 | Z28: 0 | AA28: 0 | AB28: 0 | AC28: 0 | AD28: 0 | AE28: 0 | AF28: 0 | AG28: 0 | AH28: 0 | AI28: 0 | AJ28: 0 | AK28: 0 | AL28: 0 | AM28: 0 | AN28: 0 | AO28: 0 | AP28: 0 | AQ28: 0 | AR28: 0 | AS28: 0 | AT28: 0 | AU28: 0 | AV28: 0 | AW28: 0 | AX28: 0 | AY28: 0 | AZ28: 0
A29: RESULTADOS & LUCRATIVIDADE
A30: EBITDA / LAJIDA (LUCRO ANTES DE JUROS E IMPOSTOS) | B30: -266.37 | C30: -1347.52 | D30: -4524.85 | E30: -57415.616 | F30: -59810.35 | G30: -59054.56 | H30: -49232.22 | I30: -7134.91 | J30: 54011.07 | K30: 254632.36 | L30: 896303.45 | M30: 1432123.1 | N30: 2106918.8 | O30: 2302197.7 | P30: 2432212.1 | Q30: 2677766.1 | R30: 2938323.4 | S30: 3198883.9 | T30: 3459447.7 | U30: 3720014.4 | V30: 3980584.1 | W30: 4175888.7 | X30: 4371196.1 | Y30: 4566506.2 | Z30: 4735711.8 | AA30: 4891866.4 | AB30: 5021916.2 | AC30: 5135468.5 | AD30: 5265523.3 | AE30: 5395580.4 | AF30: 5525639.8 | AG30: 5655701.4 | AH30: 5785765.3 | AI30: 5915831.3 | AJ30: 6045899.4 | AK30: 6175969.6 | AL30: 6306041.7 | AM30: 6436115.9 | AN30: 6566192 | AO30: 6678120 | AP30: 6808199.8 | AQ30: 6938281.5 | AR30: 7068365 | AS30: 7198450.2 | AT30: 7328537.1 | AU30: 7458625.8 | AV30: 7588716.1 | AW30: 6151432.8 | AX30: 7632517.5 | AY30: 7632517.5 | AZ30: 7632517.5
A31: Resultado Financeiro Líquido | B31: -26.637 | C31: -134.752 | D31: -452.485 | E31: -5741.5616 | F31: -5981.035 | G31: -5905.456 | H31: -4923.222 | I31: -713.491 | J31: 0 | K31: 0 | L31: 0 | M31: 0 | N31: 0 | O31: 0 | P31: 0 | Q31: 0 | R31: 0 | S31: 0 | T31: 0 | U31: 0 | V31: 0 | W31: 0 | X31: 0 | Y31: 0 | Z31: 0 | AA31: 0 | AB31: 0 | AC31: 0 | AD31: 0 | AE31: 0 | AF31: 0 | AG31: 0 | AH31: 0 | AI31: 0 | AJ31: 0 | AK31: 0 | AL31: 0 | AM31: 0 | AN31: 0 | AO31: 0 | AP31: 0 | AQ31: 0 | AR31: 0 | AS31: 0 | AT31: 0 | AU31: 0 | AV31: 0 | AW31: 0 | AX31: 0 | AY31: 0 | AZ31: 0
A32: Tributos sobre o Lucro (IRPJ & CSLL - Pós-Simples) | B32: 0 | C32: 0 | D32: 0 | E32: 0 | F32: 0 | G32: 0 | H32: 0 | I32: 0 | J32: 0 | K32: -109589.34 | L32: -273973.35 | M32: -410960.03 | N32: -486028.55 | O32: -527688.14 | P32: -555461.2 | Q32: -611007.32 | R32: -666553.44 | S32: -722099.56 | T32: -777645.68 | U32: -833191.8 | V32: -888737.92 | W32: -930397.51 | X32: -972057.1 | Y32: -1013716.7 | Z32: -1049821.7 | AA32: -1083149.3 | AB32: -1110922.4 | AC32: -1138695.5 | AD32: -1166468.5 | AE32: -1194241.6 | AF32: -1222014.6 | AG32: -1249787.7 | AH32: -1277560.8 | AI32: -1305333.8 | AJ32: -1333106.9 | AK32: -1360879.9 | AL32: -1388653 | AM32: -1416426.1 | AN32: -1444199.1 | AO32: -1471972.2 | AP32: -1499745.2 | AQ32: -1527518.3 | AR32: -1555291.4 | AS32: -1583064.4 | AT32: -1610837.5 | AU32: -1638610.5 | AV32: -1666383.6 | AW32: -1666383.6 | AX32: -1666383.6 | AY32: -1666383.6 | AZ32: -1666383.6
A33: LUCRO LÍQUIDO DO EXERCÍCIO | B33: -293.007 | C33: -1482.272 | D33: -4977.335 | E33: -63157.177 | F33: -65791.385 | G33: -64960.016 | H33: -54155.442 | I33: -7848.401 | J33: 54011.07 | K33: 145043.02 | L33: 622330.1 | M33: 1021163.1 | N33: 1620890.2 | O33: 1774509.6 | P33: 1876750.9 | Q33: 2066758.8 | R33: 2271770 | S33: 2476784.4 | T33: 2681802 | U33: 2886822.6 | V33: 3091846.2 | W33: 3245491.2 | X33: 3399139 | Y33: 3552789.5 | Z33: 3685890.2 | AA33: 3808717 | AB33: 3910993.8 | AC33: 3996773.1 | AD33: 4099054.8 | AE33: 4201338.8 | AF33: 4303625.2 | AG33: 4405913.7 | AH33: 4508204.5 | AI33: 4610497.5 | AJ33: 4712792.5 | AK33: 4815089.6 | AL33: 4917388.7 | AM33: 5019689.8 | AN33: 5121992.8 | AO33: 5206147.8 | AP33: 5308454.6 | AQ33: 5410763.2 | AR33: 5513073.6 | AS33: 5615385.8 | AT33: 5717699.7 | AU33: 5820015.2 | AV33: 5922332.5 | AW33: 4485049.2 | AX33: 5966133.9 | AY33: 5966133.9 | AZ33: 5966133.9
A34: LUCRO LÍQUIDO ACUMULADO (FLUXO DE CAIXA) | B34: -293.007 | C34: -1775.279 | D34: -6752.614 | E34: -69909.791 | F34: -135701.18 | G34: -200661.19 | H34: -254816.63 | I34: -262665.04 | J34: -208653.97 | K34: -63610.945 | L34: 558719.15 | M34: 1579882.2 | N34: 3200772.5 | O34: 4975282 | P34: 6852032.9 | Q34: 8918791.7 | R34: 11190562 | S34: 13667346 | T34: 16349148 | U34: 19235971 | V34: 22327817 | W34: 25573308 | X34: 28972447 | Y34: 32525237 | Z34: 36211127 | AA34: 40019844 | AB34: 43930838 | AC34: 47927611 | AD34: 52026666 | AE34: 56228004 | AF34: 60531630 | AG34: 64937543 | AH34: 69445748 | AI34: 74056245 | AJ34: 78769038 | AK34: 83584127 | AL34: 88501516 | AM34: 93521206 | AN34: 98643199 | AO34: 1.0384935e+08 | AP34: 1.091578e+08 | AQ34: 1.1456856e+08 | AR34: 1.2008164e+08 | AS34: 1.2569702e+08 | AT34: 1.3141472e+08 | AU34: 1.3723474e+08 | AV34: 1.4315707e+08 | AW34: 1.4764212e+08 | AX34: 1.5360825e+08 | AY34: 1.5957439e+08 | AZ34: 1.6554052e+08

Sheet Realizado
A1: NETFITS LTDA. — DEMONSTRAÇÃO DO RESULTADO DO EXERCÍCIO (REALIZADO / CONTABILIDADE)
A2: Acompanhamento dos Lançamentos Financeiros e Fiscais Reais Mensais
A4: Conta / Estrutura DRE | B4: Oct/26 | C4: Nov/26 | D4: Dec/26 | E4: Jan/27 | F4: Feb/27 | G4: Mar/27 | H4: Apr/27 | I4: May/27 | J4: Jun/27 | K4: Jul/27 | L4: Aug/27 | M4: Sep/27 | N4: Oct/27 | O4: Nov/27 | P4: Dec/27 | Q4: Jan/28 | R4: Feb/28 | S4: Mar/28 | T4: Apr/28 | U4: May/28 | V4: Jun/28 | W4: Jul/28 | X4: Aug/28 | Y4: Sep/28 | Z4: Oct/28 | AA4: Nov/28 | AB4: Dec/28 | AC4: Jan/29 | AD4: Feb/29 | AE4: Mar/29 | AF4: Apr/29 | AG4: May/29 | AH4: Jun/29 | AI4: Jul/29 | AJ4: Aug/29 | AK4: Sep/29 | AL4: Oct/29 | AM4: Nov/29 | AN4: Dec/29 | AO4: Jan/30 | AP4: Feb/30 | AQ4: Mar/30 | AR4: Apr/30 | AS4: May/30 | AT4: Jun/30 | AU4: Jul/30 | AV4: Aug/30 | AW4: Sep/30 | AX4: Oct/30 | AY4: Nov/30 | AZ4: Dec/30
A5: USUÁRIOS ATIVOS DA PLATAFORMA | B5: 100
A6: RECEITA BRUTA
A7: Receita Marketplace (Shop)
A8: Receita Clube de Assinatura (Fase 2)
A9: Receita Total Mídia (Feed Views & Clicks)
A10: Receita Serviços de Saúde & Parceiros
A11: Receita Venda de Pontos Corporativos (B2B)
A12: TOTAL DA RECEITA BRUTA
A13: DEDUÇÕES DA RECEITA BRUTA
A14: Impostos sobre a Receita Bruta (Simples / Lucro Presumido)
A15: RECEITA LÍQUIDA TOTAL
A16: CUSTOS DIRETOS & ENCARGOS DO PROGRAMA
A17: Despesa com Provisão de Pontos nfs (R$ 0,01/nfs)
... A34: LUCRO LÍQUIDO ACUMULADO (FLUXO DE CAIXA)

Sheet Variação Real x Orçado
A1: NETFITS LTDA. — PAINEL COMPARATIVO REAL x ORÇADO (VARIAÇÃO NOMINAL & PERCENTUAL)
A2: Análise de Desvios (Variance Analysis): Realizado (-) Orçado e % de Atingimento de Metas
A4: Conta / Estrutura DRE | B4: Oct/26 | C4: Nov/26 | D4: Dec/26 | E4: Jan/27 | F4: Feb/27 | G4: Mar/27 | H4: Apr/27 | I4: May/27 | J4: Jun/27 | K4: Jul/27 | L4: Aug/27 | M4: Sep/27 | N4: Oct/27 | O4: Nov/27 | P4: Dec/27 | Q4: Jan/28 | R4: Feb/28 | S4: Mar/28 | T4: Apr/28 | U4: May/28 | V4: Jun/28 | W4: Jul/28 | X4: Aug/28 | Y4: Sep/28 | Z4: Oct/28 | AA4: Nov/28 | AB4: Dec/28 | AC4: Jan/29 | AD4: Feb/29 | AE4: Mar/29 | AF4: Apr/29 | AG4: May/29 | AH4: Jun/29 | AI4: Jul/29 | AJ4: Aug/29 | AK4: Sep/29 | AL4: Oct/29 | AM4: Nov/29 | AN4: Dec/29 | AO4: Jan/30 | AP4: Feb/30 | AQ4: Mar/30 | AR4: Apr/30 | AS4: May/30 | AT4: Jun/30 | AU4: Jul/30 | AV4: Aug/30 | AW4: Sep/30 | AX4: Oct/30 | AY4: Nov/30 | AZ4: Dec/30
A5: USUÁRIOS ATIVOS DA PLATAFORMA | B5: =Realizado!B5-Orçado!B5 -> 0 | C5: =Realizado!C5-Orçado!C5 -> -500 | D5: =Realizado!D5-Orçado!D5 -> -1000 | E5: =Realizado!E5-Orçado!E5 -> -1333 | F5: =Realizado!F5-Orçado!F5 -> -1750 | G5: =Realizado!G5-Orçado!G5 -> -5000 | H5: =Realizado!H5-Orçado!H5 -> -15000 | I5: =Realizado!I5-Orçado!I5 -> -50000 | ... AZ5: =Realizado!AZ5-Orçado!AZ5 -> -3000000
A6: RECEITA BRUTA
A7: Receita Marketplace (Shop) | B7: =Realizado!B7-Orçado!B7 -> -80 | C7: =Realizado!C7-Orçado!C7 -> -400 | D7: =Realizado!D7-Orçado!D7 -> -800 | E7: =Realizado!E7-Orçado!E7 -> -1040 | F7: =Realizado!F7-Orçado!F7 -> -1400 | G7: =Realizado!G7-Orçado!G7 -> -4000 | H7: =Realizado!H7-Orçado!H7 -> -12000 | I7: =Realizado!I7-Orçado!I7 -> -40000 | ... AZ7: =Realizado!AZ7-Orçado!AZ7 -> -2400000
A8: Receita Clube de Assinatura (Fase 2) | B8: =Realizado!B8-Orçado!B8 -> 0 | C8: =Realizado!C8-Orçado!C8 -> 0 | D8: =Realizado!D8-Orçado!D8 -> 0 | E8: =Realizado!E8-Orçado!E8 -> 0 | F8: =Realizado!F8-Orçado!F8 -> 0 | G8: =Realizado!G8-Orçado!G8 -> 0 | H8: =Realizado!H8-Orçado!H8 -> 0 | I8: =Realizado!I8-Orçado!I8 -> 0 | ... AZ8: =Realizado!AZ8-Orçado!AZ8 -> -59700
A9: Receita Total Mídia (Feed Views & Clicks) | B9: =Realizado!B9-Orçado!B9 -> 0 | C9: =Realizado!C9-Orçado!C9 -> 0 | D9: =Realizado!D9-Orçado!D9 -> 0 | E9: =Realizado!E9-Orçado!E9 -> -119.97 | F9: =Realizado!F9-Orçado!F9 -> -315 | G9: =Realizado!G9-Orçado!G9 -> -2250 | H9: =Realizado!H9-Orçado!H9 -> -13500 | I9: =Realizado!I9-Orçado!I9 -> -45000 | ... AZ9: =Realizado!AZ9-Orçado!AZ9 -> -2700000
A10: Receita Serviços de Saúde & Parceiros | B10: =Realizado!B10-Orçado!B10 -> 0 | C10: =Realizado!C10-Orçado!C10 -> 0 | D10: =Realizado!D10-Orçado!D10 -> 0 | E10: =Realizado!E10-Orçado!E10 -> 0 | F10: =Realizado!F10-Orçado!F10 -> 0 | G10: =Realizado!G10-Orçado!G10 -> 0 | H10: =Realizado!H10-Orçado!H10 -> 0 | I10: =Realizado!I10-Orçado!I10 -> 0 | ... AZ10: =Realizado!AZ10-Orçado!AZ10 -> -169500
A11: Receita Venda de Pontos Corporativos (B2B) | B11: =Realizado!B11-Orçado!B11 -> 0 | C11: =Realizado!C11-Orçado!C11 -> 0 | D11: =Realizado!D11-Orçado!D11 -> 0 | E11: =Realizado!E11-Orçado!E11 -> 0 | F11: =Realizado!F11-Orçado!F11 -> 0 | G11: =Realizado!G11-Orçado!G11 -> 0 | H11: =Realizado!H11-Orçado!H11 -> 0 | I11: =Realizado!I11-Orçado!I11 -> 0 | ... AZ11: =Realizado!AZ11-Orçado!AZ11 -> -7200000
A12: TOTAL DA RECEITA BRUTA | B12: =Realizado!B12-Orçado!B12 -> -80 | C12: =Realizado!C12-Orçado!C12 -> -400 | D12: =Realizado!D12-Orçado!D12 -> -800 | E12: =Realizado!E12-Orçado!E12 -> -1159.97 | F12: =Realizado!F12-Orçado!F12 -> -1715 | G12: =Realizado!G12-Orçado!G12 -> -6250 | H12: =Realizado!H12-Orçado!H12 -> -25500 | I12: =Realizado!I12-Orçado!I12 -> -85000 | ... AZ12: =Realizado!AZ12-Orçado!AZ12 -> -12529200
A13: DEDUÇÕES DA RECEITA BRUTA
A14: Impostos sobre a Receita Bruta (Simples / Lucro Presumido) | B14: =Realizado!B14-Orçado!B14 -> -4.8 | C14: =Realizado!C14-Orçado!C14 -> -24 | D14: =Realizado!D14-Orçado!D14 -> -48 | E14: =Realizado!E14-Orçado!E14 -> -69.5982 | F14: =Realizado!F14-Orçado!F14 -> -102.9 | G14: =Realizado!G14-Orçado!G14 -> -375 | H14: =Realizado!H14-Orçado!H14 -> -1530 | I14: =Realizado!I14-Orçado!I14 -> -5100 | ... AZ14: =Realizado!AZ14-Orçado!AZ14 -> 0
A15: RECEITA LÍQUIDA TOTAL | B15: =Realizado!B15-Orçado!B15 -> -75.2 | C15: =Realizado!C15-Orçado!C15 -> -376 | D15: =Realizado!D15-Orçado!D15 -> -752 | E15: =Realizado!E15-Orçado!E15 -> -1090.3718 | F15: =Realizado!F15-Orçado!F15 -> -1612.1 | G15: =Realizado!G15-Orçado!G15 -> -5875 | H15: =Realizado!H15-Orçado!H15 -> -23970 | I15: =Realizado!I15-Orçado!I15 -> -79900 | ... AZ15: =Realizado!AZ15-Orçado!AZ15 -> -12529200
A16: CUSTOS DIRETOS & ENCARGOS DO PROGRAMA
A17: Despesa com Provisão de Pontos nfs (R$ 0,01/nfs) | B17: =Realizado!B17-Orçado!B17 -> -22 | C17: =Realizado!C17-Orçado!C17 -> -110 | D17: =Realizado!D17-Orçado!D17 -> -220 | E17: =Realizado!E17-Orçado!E17 -> -240.9365 | F17: =Realizado!F17-Orçado!F17 -> -321.13 | G17: =Realizado!G17-Orçado!G17 -> -958.75 | H17: =Realizado!H17-Orçado!H17 -> -3082.5 | I17: =Realizado!I17-Orçado!I17 -> -10275 | ... AZ17: =Realizado!AZ17-Orçado!AZ17 -> -4215112.5
A18: Comissões & Repasses aos Associados (10% Revenue Share) | B18: =Realizado!B18-Orçado!B18 -> 8 | C18: =Realizado!C18-Orçado!C18 -> 40 | D18: =Realizado!D18-Orçado!D18 -> 80 | E18: =Realizado!E18-Orçado!E18 -> 115.997 | F18: =Realizado!F18-Orçado!F18 -> 171.5 | G18: =Realizado!G18-Orçado!G18 -> 625 | H18: =Realizado!H18-Orçado!H18 -> 2550 | I18: =Realizado!I18-Orçado!I18 -> 8500 | ... AZ18: =Realizado!AZ18-Orçado!AZ18 -> 1252920
A19: Spread de Preço de Pontos (Emissão vs Resgate) | B19: =Realizado!B19-Orçado!B19 -> 0 | C19: =Realizado!C19-Orçado!C19 -> 0 | D19: =Realizado!D19-Orçado!D19 -> 0 | E19: =Realizado!E19-Orçado!E19 -> -55.986 | F19: =Realizado!F19-Orçado!F19 -> -73.5 | G19: =Realizado!G19-Orçado!G19 -> -210 | H19: =Realizado!H19-Orçado!H19 -> -630 | I19: =Realizado!I19-Orçado!I19 -> -2100 | ... AZ19: =Realizado!AZ19-Orçado!AZ19 -> -771000
A20: MARGEM DE CONTRIBUIÇÃO (RECEITA PÓS ENCARGOS) | B20: =Realizado!B20-Orçado!B20 -> -45.2 | C20: =Realizado!C20-Orçado!C20 -> -226 | D20: =Realizado!D20-Orçado!D20 -> -452 | E20: =Realizado!E20-Orçado!E20 -> -789.4243 | F20: =Realizado!F20-Orçado!F20 -> -1192.97 | G20: =Realizado!G20-Orçado!G20 -> -4501.25 | H20: =Realizado!H20-Orçado!H20 -> -18967.5 | I20: =Realizado!I20-Orçado!I20 -> -63225 | ... AZ20: =Realizado!AZ20-Orçado!AZ20 -> -7832167.5
A21: DESPESAS OPERACIONAIS (OPEX)
A22: 1. Pessoal & Pró-Labore da Diretoria | B22: =Realizado!B22-Orçado!B22 -> 0 | C22: =Realizado!C22-Orçado!C22 -> 0 | D22: =Realizado!D22-Orçado!D22 -> 0 | E22: =Realizado!E22-Orçado!E22 -> 50000 | F22: =Realizado!F22-Orçado!F22 -> 50000 | G22: =Realizado!G22-Orçado!G22 -> 50000 | H22: =Realizado!H22-Orçado!H22 -> 50000 | I22: =Realizado!I22-Orçado!I22 -> 50000 | ... AZ22: =Realizado!AZ22-Orçado!AZ22 -> 199650
A23: 2. Squad de Agentes de IA Autônomos (8 Operação + 4 QA) | B23: =Realizado!B23-Orçado!B23 -> 71.72 | C23: =Realizado!C23-Orçado!C23 -> 251 | D23: =Realizado!D23-Orçado!D23 -> 605.19 | E23: =Realizado!E23-Orçado!E23 -> 885.07 | F23: =Realizado!F23-Orçado!F23 -> 1105.78 | G23: =Realizado!G23-Orçado!G23 -> 1295.19 | H23: =Realizado!H23-Orçado!H23 -> 1381.83 | I23: =Realizado!I23-Orçado!I23 -> 1464.28 | ... AZ23: =Realizado!AZ23-Orçado!AZ23 -> 114637.37
A24: 3. Infraestrutura Cloud, Servidores & Edge (Nitro/Cloudflare) | B24: =Realizado!B24-Orçado!B24 -> 111.51 | C24: =Realizado!C24-Orçado!C24 -> 595.6 | D24: =Realizado!D24-Orçado!D24 -> 1925.93 | E24: =Realizado!E24-Orçado!E24 -> 3194.47 | F24: =Realizado!F24-Orçado!F24 -> 4295.56 | G24: =Realizado!G24-Orçado!G24 -> 5300.34 | H24: =Realizado!H24-Orçado!H24 -> 5776.77 | I24: =Realizado!I24-Orçado!I24 -> 6239.16 | ... AZ24: =Realizado!AZ24-Orçado!AZ24 -> 581094.34
A25: 4. Estrutura de Dados, Ledger & Analytics (Postgres/BigQuery) | B25: =Realizado!B25-Orçado!B25 -> 84.91 | C25: =Realizado!C25-Orçado!C25 -> 471.92 | D25: =Realizado!D25-Orçado!D25 -> 1565.4 | E25: =Realizado!E25-Orçado!E25 -> 2623.76 | F25: =Realizado!F25-Orçado!F25 -> 3549.26 | G25: =Realizado!G25-Orçado!G25 -> 4397.82 | H25: =Realizado!H25-Orçado!H25 -> 4801.26 | I25: =Realizado!I25-Orçado!I25 -> 5193.42 | ... AZ25: =Realizado!AZ25-Orçado!AZ25 -> 490394.27
A26: 5. CRM, WhatsApp API Transacional & Mensageria Omnichannel | B26: =Realizado!B26-Orçado!B26 -> 21.09 | C26: =Realizado!C26-Orçado!C26 -> 130 | D26: =Realizado!D26-Orçado!D26 -> 463.66 | E26: =Realizado!E26-Orçado!E26 -> 801.86 | F26: =Realizado!F26-Orçado!F26 -> 1104.78 | G26: =Realizado!G26-Orçado!G26 -> 1386.84 | H26: =Realizado!H26-Orçado!H26 -> 1522.14 | I26: =Realizado!I26-Orçado!I26 -> 1654.34 | ... AZ26: =Realizado!AZ26-Orçado!AZ26 -> 163369.7
A27: 6. Segurança, Observabilidade & Ferramentas FinOps | B27: =Realizado!B27-Orçado!B27 -> 22.34 | C27: =Realizado!C27-Orçado!C27 -> 125 | D27: =Realizado!D27-Orçado!D27 -> 416.67 | E27: =Realizado!E27-Orçado!E27 -> 699.88 | F27: =Realizado!F27-Orçado!F27 -> 947.94 | G27: =Realizado!G27-Orçado!G27 -> 1175.62 | H27: =Realizado!H27-Orçado!H27 -> 1283.94 | I27: =Realizado!I27-Orçado!I27 -> 1389.26 | ... AZ27: =Realizado!AZ27-Orçado!AZ27 -> 131589.01
A28: 7. Despesas Administrativas & Gerais | B28: =Realizado!B28-Orçado!B28 -> 0 | C28: =Realizado!C28-Orçado!C28 -> 0 | D28: =Realizado!D28-Orçado!D28 -> 0 | E28: =Realizado!E28-Orçado!E28 -> 0 | F28: =Realizado!F28-Orçado!F28 -> 0 | G28: =Realizado!G28-Orçado!G28 -> 0 | H28: =Realizado!H28-Orçado!H28 -> 0 | I28: =Realizado!I28-Orçado!I28 -> 0 | ... AZ28: =Realizado!AZ28-Orçado!AZ28 -> 0
A29: RESULTADOS & LUCRATIVIDADE
A30: EBITDA / LAJIDA (LUCRO ANTES DE JUROS E IMPOSTOS) | B30: =Realizado!B30-Orçado!B30 -> 266.37 | C30: =Realizado!C30-Orçado!C30 -> 1347.52 | D30: =Realizado!D30-Orçado!D30 -> 4524.85 | E30: =Realizado!E30-Orçado!E30 -> 57415.616 | F30: =Realizado!F30-Orçado!F30 -> 59810.35 | G30: =Realizado!G30-Orçado!G30 -> 59054.56 | H30: =Realizado!H30-Orçado!H30 -> 49232.22 | I30: =Realizado!I30-Orçado!I30 -> 7134.91 | ... AZ30: =Realizado!AZ30-Orçado!AZ30 -> -7632517.5
A31: Resultado Financeiro Líquido | B31: =Realizado!B31-Orçado!B31 -> 26.637 | C31: =Realizado!C31-Orçado!C31 -> 134.752 | D31: =Realizado!D31-Orçado!D31 -> 452.485 | E31: =Realizado!E31-Orçado!E31 -> 5741.5616 | F31: =Realizado!F31-Orçado!F31 -> 5981.035 | G31: =Realizado!G31-Orçado!G31 -> 5905.456 | H31: =Realizado!H31-Orçado!H31 -> 4923.222 | I31: =Realizado!I31-Orçado!I31 -> 713.491 | ... AZ31: =Realizado!AZ31-Orçado!AZ31 -> 0
A32: Tributos sobre o Lucro (IRPJ & CSLL - Pós-Simples) | B32: =Realizado!B32-Orçado!B32 -> 0 | C32: =Realizado!C32-Orçado!C32 -> 0 | D32: =Realizado!D32-Orçado!D32 -> 0 | E32: =Realizado!E32-Orçado!E32 -> 0 | F32: =Realizado!F32-Orçado!F32 -> 0 | G32: =Realizado!G32-Orçado!G32 -> 0 | H32: =Realizado!H32-Orçado!H32 -> 0 | I32: =Realizado!I32-Orçado!I32 -> 0 | ... AZ32: =Realizado!AZ32-Orçado!AZ32 -> 1666383.6
A33: LUCRO LÍQUIDO DO EXERCÍCIO | B33: =Realizado!B33-Orçado!B33 -> 293.007 | C33: =Realizado!C33-Orçado!C33 -> 1482.272 | D33: =Realizado!D33-Orçado!D33 -> 4977.335 | E33: =Realizado!E33-Orçado!E33 -> 63157.177 | F33: =Realizado!F33-Orçado!F33 -> 65791.385 | G33: =Realizado!G33-Orçado!G33 -> 64960.016 | H33: =Realizado!H33-Orçado!H33 -> 54155.442 | I33: =Realizado!I33-Orçado!I33 -> 7848.401 | ... AZ33: =Realizado!AZ33-Orçado!AZ33 -> -5966133.9
A34: LUCRO LÍQUIDO ACUMULADO (FLUXO DE CAIXA) | B34: =Realizado!B34-Orçado!B34 -> 293.007 | C34: =Realizado!C34-Orçado!C34 -> 1775.279 | D34: =Realizado!D34-Orçado!D34 -> 6752.614 | E34: =Realizado!E34-Orçado!E34 -> 69909.791 | F34: =Realizado!F34-Orçado!F34 -> 135701.18 | G34: =Realizado!G34-Orçado!G34 -> 200661.19 | H34: =Realizado!H34-Orçado!H34 -> 254816.63 | I34: =Realizado!I34-Orçado!I34 -> 262665.04 | ... AZ34: =Realizado!AZ34-Orçado!AZ34 -> -1.6554052e+08

Sheet Dashboard Executivo
A1: NETFITS LTDA. — DASHBOARD EXECUTIVO REAL x ORÇADO (2026 A 2030)
A2: Visão Executiva Consolidada por Ano, Margens Operacionais e Indicadores de Tração
A4: VPL DO FLUXO DE CAIXA (DEZ/30) | C4: TOTAL USUÁRIOS (DEZ/2030) | E4: RECEITA BRUTA ANUAL (2030) | G4: ECONOMIA FINOPS IA SQUADS
A5: R$ 116.219.061,57 | C5: 3.000.000 Atletas | E5: R$ 102.730.000,00 | G5: R$ 1.395.736,80 / ano
A6: Taxa de Desconto: 1% a.m. | C6: Meta Nacional Atingida | E6: Marketplace + Mídia + B2B | G6: 97,6% Redução de OPEX
A8: INDICADOR CONSOLIDADO (R$) | B8: 2026 (Launch) | C8: 2027 (Scale) | D8: 2028 (Growth) | E8: 2029 (Expansion) | F8: 2030 (Maturity) | G8: TOTAL ACUMULADO
A9: Usuários Ativos (Fim de Período) | B9: 1000 | C9: 1000000 | D9: 2000000 | E9: 2600000 | F9: 3000000 | G9: 3000000
A10: Receita Bruta Orçada (R$) | B10: 1280 | C10: 11463994 | D10: 49767200 | E10: 77017200 | F10: 102730000 | G10: 2.4097967e+08
A11: Receita Líquida Orçada (R$) | B11: 1203.2 | C11: 10776155 | D11: 46781168 | E11: 72396168 | F11: 96566200 | G11: 2.2652089e+08
A12: Repasses Associados / Embaixadores | B12: -128 | C12: -1146399.4 | D12: -4976720 | E12: -7701720 | F12: -10273000 | G12: -24097967
A13: Provisão de Pontos nfs (Custo Direto) | B13: -352 | C13: -2955078.8 | D13: -10500000 | E13: -13500000 | F13: -15000000 | G13: -41955431
A14: OPEX Total (Squads IA + Cloud + Pessoal) | B14: -934.7 | C14: -423208.7 | D14: -1950000 | E14: -2450000 | F14: -2950000 | G14: -7774143.4
A15: EBITDA / LAJIDA Orçado (R$) | B15: -211.5 | C15: 6251467.8 | D15: 29354448 | E15: 48744448 | F15: 68343200 | G15: 1.5269335e+08
A16: Lucro Líquido do Exercício (R$) | B16: -6752.6 | C16: 6858785.5 | D16: 37078805 | E16: 54712361 | F16: 66897323 | G16: 1.6554052e+08
A17: Margem Líquida (%) | B17: -527,5% | C17: 59,8% | D17: 74,5% | E17: 71,0% | F17: 65,1% | G17: 68,7%
